<?xml version="1.0" encoding="utf-8"?>
<!-- This URDF was automatically created by SolidWorks to URDF Exporter! Originally created by Stephen Brawner (brawner@gmail.com) 
     Commit Version: 1.5.1-0-g916b5db  Build Version: 1.5.7152.31018
     For more information, please see http://wiki.ros.org/sw_urdf_exporter -->
<robot
  name="car_description">
  <link
    name="base_link">
    <inertial>
      <origin
        xyz="-0.0012799 -2.2763E-18 0.04967"
        rpy="0 0 0" />
      <mass
        value="10.311" />
      <inertia
        ixx="0.04304"
        ixy="-3.6932E-18"
        ixz="0.0005894"
        iyy="0.24042"
        iyz="1.4E-19"
        izz="0.26648" />
    </inertial>
    <visual>
      <origin
        xyz="0 0 0"
        rpy="0 0 0" />
      <geometry>
        <mesh
          filename="package://car_description/meshes/base_link.STL" />
      </geometry>
      <material
        name="">
        <color
          rgba="0.75294 0.75294 0.75294 1" />
      </material>
    </visual>
    <collision>
      <origin
        xyz="0 0 0"
        rpy="0 0 0" />
      <geometry>
        <mesh
          filename="package://car_description/meshes/base_link.STL" />
      </geometry>
    </collision>
  </link>
  <link
    name="lbwheel_link">
    <inertial>
      <origin
        xyz="0 -0.00051546 1.7347E-18"
        rpy="0 0 0" />
      <mass
        value="0.68565" />
      <inertia
        ixx="0.00083283"
        ixy="-5.9331E-20"
        ixz="-2.732E-20"
        iyy="0.0012217"
        iyz="-8.3558E-21"
        izz="0.00083283" />
    </inertial>
    <visual>
      <origin
        xyz="0 0 0"
        rpy="0 0 0" />
      <geometry>
        <mesh
          filename="package://car_description/meshes/lbwheel_link.STL" />
      </geometry>
      <material
        name="">
        <color
          rgba="0.75294 0.75294 0.75294 1" />
      </material>
    </visual>
    <collision>
      <origin
        xyz="0 0 0"
        rpy="0 0 0" />
      <geometry>
        <mesh
          filename="package://car_description/meshes/lbwheel_link.STL" />
      </geometry>
    </collision>
  </link>
  <joint
    name="lbwheel_joint"
    type="continuous">
    <origin
      xyz="-0.175 0.16 0.015"
      rpy="0 0 0" />
    <parent
      link="base_link" />
    <child
      link="lbwheel_link" />
    <axis
      xyz="0 1 0" />
  </joint>
  <link
    name="rbwheel_link">
    <inertial>
      <origin
        xyz="0 0.00051546 0"
        rpy="0 0 0" />
      <mass
        value="0.68565" />
      <inertia
        ixx="0.00083283"
        ixy="1.2107E-20"
        ixz="-1.721E-20"
        iyy="0.0012217"
        iyz="-3.4783E-20"
        izz="0.00083283" />
    </inertial>
    <visual>
      <origin
        xyz="0 0 0"
        rpy="0 0 0" />
      <geometry>
        <mesh
          filename="package://car_description/meshes/rbwheel_link.STL" />
      </geometry>
      <material
        name="">
        <color
          rgba="0.75294 0.75294 0.75294 1" />
      </material>
    </visual>
    <collision>
      <origin
        xyz="0 0 0"
        rpy="0 0 0" />
      <geometry>
        <mesh
          filename="package://car_description/meshes/rbwheel_link.STL" />
      </geometry>
    </collision>
  </link>
  <joint
    name="rbwheel_joint"
    type="continuous">
    <origin
      xyz="-0.175 -0.16 0.015"
      rpy="0 0 0" />
    <parent
      link="base_link" />
    <child
      link="rbwheel_link" />
    <axis
      xyz="0 1 0" />
  </joint>
  <link
    name="lfwheel_link">
    <inertial>
      <origin
        xyz="0 -0.000515463917525771 0"
        rpy="0 0 0" />
      <mass
        value="0.685652596645972" />
      <inertia
        ixx="0.000832831974251694"
        ixy="-1.18757953331747E-20"
        ixz="-1.58578700929054E-36"
        iyy="0.00122165002762582"
        iyz="2.14850603386636E-36"
        izz="0.000832831974251694" />
    </inertial>
    <visual>
      <origin
        xyz="0 0 0"
        rpy="0 0 0" />
      <geometry>
        <mesh
          filename="package://car_description/meshes/lfwheel_link.STL" />
      </geometry>
      <material
        name="">
        <color
          rgba="0.752941176470588 0.752941176470588 0.752941176470588 1" />
      </material>
    </visual>
    <collision>
      <origin
        xyz="0 0 0"
        rpy="0 0 0" />
      <geometry>
        <mesh
          filename="package://car_description/meshes/lfwheel_link.STL" />
      </geometry>
    </collision>
  </link>
  <joint
    name="lfwheel_joint"
    type="continuous">
    <origin
      xyz="0.16 0.16517 0.015"
      rpy="0 0 0" />
    <parent
      link="base_link" />
    <child
      link="lfwheel_link" />
    <axis
      xyz="0 1 0" />
  </joint>
  <link
    name="rfwheel_link">
    <inertial>
      <origin
        xyz="0 0.000515463917525771 3.46944695195361E-18"
        rpy="0 0 0" />
      <mass
        value="0.685652596645972" />
      <inertia
        ixx="0.000832831974251694"
        ixy="3.05523237444948E-20"
        ixz="1.11388141286391E-20"
        iyy="0.00122165002762582"
        iyz="-6.07509254123777E-20"
        izz="0.000832831974251694" />
    </inertial>
    <visual>
      <origin
        xyz="0 0 0"
        rpy="0 0 0" />
      <geometry>
        <mesh
          filename="package://car_description/meshes/rfwheel_link.STL" />
      </geometry>
      <material
        name="">
        <color
          rgba="0.752941176470588 0.752941176470588 0.752941176470588 1" />
      </material>
    </visual>
    <collision>
      <origin
        xyz="0 0 0"
        rpy="0 0 0" />
      <geometry>
        <mesh
          filename="package://car_description/meshes/rfwheel_link.STL" />
      </geometry>
    </collision>
  </link>
  <joint
    name="rfwheel_joint"
    type="continuous">
    <origin
      xyz="0.16 -0.16 0.015"
      rpy="0 0 0" />
    <parent
      link="base_link" />
    <child
      link="rfwheel_link" />
    <axis
      xyz="0 1 0" />
  </joint>
  <link
    name="laser_link">
    <inertial>
      <origin
        xyz="2.7756E-17 1.8608E-19 -0.012942"
        rpy="0 0 0" />
      <mass
        value="0.25036" />
      <inertia
        ixx="0.00017163"
        ixy="-7.3468E-37"
        ixz="-1.3354E-20"
        iyy="0.00017163"
        iyz="0"
        izz="0.00028083" />
    </inertial>
    <visual>
      <origin
        xyz="0 0 0"
        rpy="0 0 0" />
      <geometry>
        <mesh
          filename="package://car_description/meshes/laser_link.STL" />
      </geometry>
      <material
        name="">
        <color
          rgba="0.75294 0.75294 0.75294 1" />
      </material>
    </visual>
    <collision>
      <origin
        xyz="0 0 0"
        rpy="0 0 0" />
      <geometry>
        <mesh
          filename="package://car_description/meshes/laser_link.STL" />
      </geometry>
    </collision>
  </link>
  <joint
    name="laser_joint"
    type="fixed">
    <origin
      xyz="0.16 0 0.12"
      rpy="0 0 0" />
    <parent
      link="base_link" />
    <child
      link="laser_link" />
    <axis
      xyz="0 0 0" />
  </joint>
  <link
    name="camera_link">
    <inertial>
      <origin
        xyz="-0.00750000000000001 -9.46049530208796E-19 -6.93889390390723E-18"
        rpy="0 0 0" />
      <mass
        value="0.003375" />
      <inertia
        ixx="1.265625E-07"
        ixy="4.32918539341672E-24"
        ixz="-2.28825950700749E-24"
        iyy="1.265625E-07"
        iyz="0"
        izz="1.265625E-07" />
    </inertial>
    <visual>
      <origin
        xyz="0 0 0"
        rpy="0 0 0" />
      <geometry>
        <mesh
          filename="package://car_description/meshes/camera_link.STL" />
      </geometry>
      <material
        name="">
        <color
          rgba="0.752941176470588 0.752941176470588 0.752941176470588 1" />
      </material>
    </visual>
    <collision>
      <origin
        xyz="0 0 0"
        rpy="0 0 0" />
      <geometry>
        <mesh
          filename="package://car_description/meshes/camera_link.STL" />
      </geometry>
    </collision>
  </link>
  <joint
    name="camera_joint"
    type="fixed">
    <origin
      xyz="0.27 0 0.05"
      rpy="0 0 0" />
    <parent
      link="base_link" />
    <child
      link="camera_link" />
    <axis
      xyz="0 0 0" />
  </joint>
</robot>